Workbook
Name _35010NE2: 'DESPIECE (MATANALYSIS)'!$B$16:$B$30
Name _35010NE2: #REF!

Sheet DESPIECE (MATANALYSIS)
G2: DECOR
E3: SISTEMA PARA INTERIOR
B5: DESPIECE DE MATERIAL | C5: XXXX | G5: SISTEMA PUERTAS INTERIOR
B7: Código de Proyecto | C7: 20250081 | G7: =TODAY() -> 45761
B8: Cliente | C8: Neometal / Joan López
B9: Referencia | C9: Javi y Pepa
B12: Ref. DECOR | C12: Descripción | E12: Uds | F12: PVP | G12: TOT
A13: G | B13: 35007LC63 | C13: =IFERROR(VLOOKUP($B13,Tarifa_all_20240711!$A$2:$G$660,2,FALSE()),"-") -> GUIA SUP TECHO PLUS LAC.6 ESP.2-3 MTS | E13: 1 | F13: =IFERROR(VLOOKUP($B13,Tarifa_all_20240711!$A$2:$G$660,5,FALSE()),"-") -> 71.7075 | G13: =IFERROR(E13*F13,"-") -> 71.7075 | H13: NEGRO TEXT.
A14: G2 | B14: 35058NE | C14: =IFERROR(VLOOKUP($B14,Tarifa_all_20240711!$A$2:$G$660,2,FALSE()),"-") -> TAPETA LAT. GUIA TECHO NEGRO | E14: 2 | F14: =IFERROR(VLOOKUP($B14,Tarifa_all_20240711!$A$2:$G$660,5,FALSE()),"-") -> 10.485 | G14: =IFERROR(E14*F14,"-") -> 20.97
A15: G3 | C15: =IFERROR(VLOOKUP($B15,Tarifa_all_20240711!$A$2:$G$660,2,FALSE()),"-") -> - | F15: =IFERROR(VLOOKUP($B15,Tarifa_all_20240711!$A$2:$G$660,5,FALSE()),"-") -> - | G15: =IFERROR(E15*F15,"-") -> -
A16: AM | B16: 35040SA | C16: =IFERROR(VLOOKUP($B16,Tarifa_all_20240711!$A$2:$G$660,2,FALSE()),"-") -> KIT AMORTIGUADOR SKY BIDIRECCIONAL 60KG | E16: 1 | F16: =IFERROR(VLOOKUP($B16,Tarifa_all_20240711!$A$2:$G$660,5,FALSE()),"-") -> 30.6 | G16: =IFERROR(E16*F16,"-") -> 30.6
A17: KP | B17: 35004NT | C17: =IFERROR(VLOOKUP($B17,Tarifa_all_20240711!$A$2:$G$660,2,FALSE()),"-") -> KIT PUERTA PA CORREDERA LAC.NEGRO TEXTURADO | E17: 1 | F17: =IFERROR(VLOOKUP($B17,Tarifa_all_20240711!$A$2:$G$660,5,FALSE()),"-") -> 215.655 | G17: =IFERROR(E17*F17,"-") -> 215.655
A18: CRR | B18: 35037SA | C18: =IFERROR(VLOOKUP($B18,Tarifa_all_20240711!$A$2:$G$660,2,FALSE()),"-") -> CARRO SKY MADERA 60KG | E18: 1 | F18: =IFERROR(VLOOKUP($B18,Tarifa_all_20240711!$A$2:$G$660,5,FALSE()),"-") -> 16.635 | G18: =IFERROR(E18*F18,"-") -> 16.635
A19: TIR | B19: 35054NT | C19: =IFERROR(VLOOKUP($B19,Tarifa_all_20240711!$A$2:$G$660,2,FALSE()),"-") -> TIRADOR RECT.ADH CAVE LAC.NEGRO TEXTURADO: 2 UDS | E19: 1 | F19: =IFERROR(VLOOKUP($B19,Tarifa_all_20240711!$A$2:$G$660,5,FALSE()),"-") -> 59.1225 | G19: =IFERROR(E19*F19,"-") -> 59.1225
A20: G/A | B20: 35027NT | C20: =IFERROR(VLOOKUP($B20,Tarifa_all_20240711!$A$2:$G$660,2,FALSE()),"-") -> GUIADOR FIJO PA LAC.NEGRO TEXTURADO | E20: 1 | F20: =IFERROR(VLOOKUP($B20,Tarifa_all_20240711!$A$2:$G$660,5,FALSE()),"-") -> 8.61 | G20: =IFERROR(E20*F20,"-") -> 8.61
A21: E/D | B21: 35006NT | C21: =IFERROR(VLOOKUP($B21,Tarifa_all_20240711!$A$2:$G$660,2,FALSE()),"-") -> PERFIL EMBELL.HORIZ. ADH LAC.NEGRO TEXTURADO | E21: 18 | F21: =IFERROR(VLOOKUP($B21,Tarifa_all_20240711!$A$2:$G$660,5,FALSE()),"-") -> 21.795 | G21: =IFERROR(E21*F21,"-") -> 392.31
B22: 35903NT30 | C22: =IFERROR(VLOOKUP($B22,Tarifa_all_20240711!$A$2:$G$660,2,FALSE()),"-") -> MARCO FIJOS 35MM D-DECOR FIJO NEGRO TEXT 3 MTS | E22: 6 | F22: =IFERROR(VLOOKUP($B22,Tarifa_all_20240711!$A$2:$G$660,5,FALSE()),"-") -> 27.7125 | G22: =IFERROR(E22*F22,"-") -> 166.275
B23: 35901NT30 | C23: =IFERROR(VLOOKUP($B23,Tarifa_all_20240711!$A$2:$G$660,2,FALSE()),"-") -> ANCLAJE TAPA 35MM D-DECOR FIJO NEGRO TEXT 3 MTS | E23: 6 | F23: =IFERROR(VLOOKUP($B23,Tarifa_all_20240711!$A$2:$G$660,5,FALSE()),"-") -> 13.4175 | G23: =IFERROR(E23*F23,"-") -> 80.505
B24: 35905NT30 | C24: =IFERROR(VLOOKUP($B24,Tarifa_all_20240711!$A$2:$G$660,2,FALSE()),"-") -> TAPA MARCO 35MM D-DECOR FIJO NEGRO TEXT 3 MTS | E24: 6 | F24: =IFERROR(VLOOKUP($B24,Tarifa_all_20240711!$A$2:$G$660,5,FALSE()),"-") -> 11.3025 | G24: =IFERROR(E24*F24,"-") -> 67.815
B25: 35902NT30 | C25: =IFERROR(VLOOKUP($B25,Tarifa_all_20240711!$A$2:$G$660,2,FALSE()),"-") -> PERFIL MINIMALISTA D-DECOR FIJO NEGRO TEXT 3 MTS | E25: 1 | F25: =IFERROR(VLOOKUP($B25,Tarifa_all_20240711!$A$2:$G$660,5,FALSE()),"-") -> 36.72 | G25: =IFERROR(E25*F25,"-") -> 36.72
B26: 35015SA | C26: =IFERROR(VLOOKUP($B26,Tarifa_all_20240711!$A$2:$G$660,2,FALSE()),"-") -> Tope Domo Decor | E26: 8 | F26: =IFERROR(VLOOKUP($B26,Tarifa_all_20240711!$A$2:$G$660,5,FALSE()),"-") -> 1.4175 | G26: =IFERROR(E26*F26,"-") -> 11.34
B27: 35017SA | C27: =IFERROR(VLOOKUP($B27,Tarifa_all_20240711!$A$2:$G$660,2,FALSE()),"-") -> PERFIL 3 MTS REDUCTOR PARA VIDRIO 6mm | E27: 7 | F27: =IFERROR(VLOOKUP($B27,Tarifa_all_20240711!$A$2:$G$660,5,FALSE()),"-") -> 3.4275 | G27: =IFERROR(E27*F27,"-") -> 23.9925
B28: 31229 | C28: =IFERROR(VLOOKUP($B28,Tarifa_all_20240711!$A$2:$G$660,2,FALSE()),"-") -> COMPLEMENTO FIJACION DOMO DECOR: BARRAS 3 MTS | E28: 8 | F28: =IFERROR(VLOOKUP($B28,Tarifa_all_20240711!$A$2:$G$660,5,FALSE()),"-") -> 11.3175 | G28: =IFERROR(E28*F28,"-") -> 90.54
B29: CUAD45 | C29: CUADRADO 45, BARRAS 6,5 MTS | E29: 1 | F29: 48.42 | G29: =IFERROR(E29*F29,"-") -> 48.42
C30: =IFERROR(VLOOKUP($B30,Tarifa_all_20240711!$A$2:$G$660,2,FALSE()),"-") -> - | F30: =IFERROR(VLOOKUP($B30,Tarifa_all_20240711!$A$2:$G$660,5,FALSE()),"-") -> - | G30: =IFERROR(E30*F30,"-") -> -
G31: =SUM(G13:G30) -> 1341.2175 | H31: 0.05 | I31: =G31*(1+H31) -> 1408.2784
B33: OBSERVACIONES:
B34: Acabado: | C34: LAC. NEGRO TEXTURADO
B35: Sistema para vidrio 6 mm. (No incluido)
B36: Precios Netos, con descuentos aplicados y a falta de impuestos
C43: PUERTA CORREDERA | D43: PUERTA pivotante
C44: COLOR | D44: COLOR
C45: DIMENSIONES | D45: DIMENSIONES
C46: KIT PUERTA | D46: KIT MARCO
C47: GUÍA TECHO/PARED | D47: KIT PUERTA
C48: CARROS | D48: CERRADURA
C49: AMORTIGUADOR | D49: MANETA
C50: DIVISORES/EMBELLECEDORES | D50: DIVISORES/EMBELLECEDORES
C51: TIRADORES | D51: ACCESORIOS
C52: ACCESORIOS (kit anclajes techo)
...

Sheet DESCRIPCIÓN (VALVENTN)
E2: DOMO DECOR
E3: SISTEMA PARA INTERIOR
A6: DESCRIPCIÓN | G6: SISTEMA PUERTAS INTERIOR
A9: Cliente: | B9: Neometal / Joan López | F9: Fecha: | G9: =TODAY() -> 45761
A10: Referencia: | B10: Corredera y Fijos | F10: Código: | G10: 20250081
A31: Características:
A32: Medidas: | B32: AN x AL mm
A33: Acabado: | B33: ='DESPIECE (MATANALYSIS)'!C34 -> LAC. NEGRO TEXTURADO
A34: Vidrio: | B34: 3+3 (no incluido)
A35: Guía: | B35: Empotrada desmontable
A36: Amortig.
A37: Carros
A38: Tirador: | B38: CAVE adhesivo.
A39: Guiador: | B39: Arrastre derecha.
A40: Embellecedor: | B40: Sí
A42: Observaciones:
A43: Vidrio NO incluido
A47: TOTAL | F47: ='DESPIECE (MATANALYSIS)'!G31 -> 1341.2175
A48: Precios Netos, IVA NO INCLUIDO
D50: PUERTA CORREDERA
D51: COLOR
D52: DIMENSIONES
D53: GUÍA TECHO/PARED
D54: CARROS
D55: AMORTIGUADOR
D56: KIT PUERTA
D57: DIVISORES/EMBELLECEDORES
D58: TIRADORES
D59: ACCESORIOS

Sheet ACABADOS
A1: Acabados
A2: LAC. NEGRO TEXTURADO
A3: LAC. BLANCO MATE
A4: LAC. MARS
A5: ANOD. PLATA MATE

Sheet Tarifa_all_20240229
A2: Ref. | B2: Descripción | C2: Pr. Tarifa | D2: % Dto | E2: PVP | F2: Familia | G2: Cod.Fam.
A3: 31229 | B3: COMPLEMENTO FIJACION DOMO DECOR: BARRAS 3 MTS | C3: 13.72 | D3: 0.2 | E3: =C3*(1-D3) -> 10.976 | F3: DOMO DECOR FIJO | G3: 302F
A4: 35000AP | B4: MARCO PA PICAP/COND ANOD.PLATA MATE | C4: 284.96 | D4: 0.2 | E4: =C4*(1-D4) -> 227.968 | F4: DOMO DECOR MOVIL | G4: 302M
A5: 35000BL | B5: MARCO PA PICAP/COND LAC.BLANCO MATE 9003 | C5: 293.63 | D5: 0.2 | E5: =C5*(1-D5) -> 234.904 | F5: DOMO DECOR MOVIL | G5: 302M
A6: 35000BLXL | B6: MARCO PA PICAP/COND LAC.BLANCO MATE 9003 XL | C6: 587.26 | D6: 0.2 | E6: =C6*(1-D6) -> 469.808 | F6: DOMO DECOR MOVIL | G6: 302M
A7: 35000CRXL | B7: MARCO PA PICAP/COND CRUDO XL | C7: 460.33 | D7: 0.2 | E7: =C7*(1-D7) -> 368.264 | F7: DOMO DECOR MOVIL | G7: 302M
A8: 35000LC2 | B8: MARCO PA PICAP/COND LACADO 2 ESTANDAR | C8: 305.38 | D8: 0.2 | E8: =C8*(1-D8) -> 244.304 | F8: DOMO DECOR MOVIL | G8: 302M
A9: 35000LC3 | B9: MARCO PA PICAP/COND LACADO 3 ESP. 1 | C9: 314.18 | D9: 0.2 | E9: =C9*(1-D9) -> 251.344 | F9: DOMO DECOR MOVIL | G9: 302M
A10: 35000LC5 | B10: MARCO PA PICAP/COND LACADO 5 MADERA | C10: 352.36 | D10: 0.2 | E10: =C10*(1-D10) -> 281.888 | F10: DOMO DECOR MOVIL | G10: 302M
A11: 35000LC6 | B11: MARCO PA PICAP/COND LACADO 6 ESP. 2 | C11: 322.99 | D11: 0.2 | E11: =C11*(1-D11) -> 258.392 | F11: DOMO DECOR MOVIL | G11: 302M
A12: 35000LC7 | B12: MARCO PA PICAP/COND LACADO 7 ESP. 3 | C12: 337.67 | D12: 0.2 | E12: =C12*(1-D12) -> 270.136 | F12: DOMO DECOR MOVIL | G12: 302M
A13: 35000MS | B13: MARCO PA PICAP/COND LAC.MARS (OXIDO) | C13: 296.63 | D13: 0.2 | E13: =C13*(1-D13) -> 237.304 | F13: DOMO DECOR MOVIL | G13: 302M
A14: 35000NE | B14: MARCO PA PICAP/COND LAC.NEGRO MATE | C14: 293.63 | D14: 0.2 | E14: =C14*(1-D14) -> 234.904 | F14: DOMO DECOR MOVIL | G14: 302M
A15: 35000NT | B15: MARCO PA PICAP/COND LAC.NEGRO TEXTURADO | C15: 293.63 | D15: 0.2 | E15: =C15*(1-D15) -> 234.904 | F15: DOMO DECOR MOVIL | G15: 302M
... A656: 35908NT65 | B656: TAPA MARCO 46MM D-DECOR FIJO NEGRO TEXTURADO 6,5 MTS | C656: 27.59 | D656: 0.2 | E656: =C656*(1-D656) -> 22.072 | F656: DOMO DECOR FIJO | G656: 302F

Sheet Tarifa_all_20240711
A1: Ref. | B1: Descripción | C1: Pr. Tarifa | D1: % Dto | E1: PVP | F1: Familia | G1: Cod.Fam.
A2: 31229 | B2: COMPLEMENTO FIJACION DOMO DECOR: BARRAS 3 MTS | C2: 15.09 | D2: 0.25 | E2: =C2*(1-D2) -> 11.3175 | F2: DOMO DECOR FIJO | G2: 302F
A3: 35000AP | B3: MARCO PA PICAP/COND ANOD.PLATA MATE | C3: 313.46 | D3: 0.25 | E3: =C3*(1-D3) -> 235.095 | F3: DOMO DECOR MOVIL | G3: 302M
A4: 35000BL | B4: MARCO PA PICAP/COND LAC.BLANCO MATE 9003 | C4: 322.99 | D4: 0.25 | E4: =C4*(1-D4) -> 242.2425 | F4: DOMO DECOR MOVIL | G4: 302M
A5: 35000BLXL | B5: MARCO PA PICAP/COND LAC.BLANCO MATE 9003 XL | C5: 645.99 | D5: 0.25 | E5: =C5*(1-D5) -> 484.4925 | F5: DOMO DECOR MOVIL | G5: 302M
A6: 35000LC2 | B6: MARCO PA PICAP/COND LACADO 2 ESTANDAR | C6: 335.92 | D6: 0.25 | E6: =C6*(1-D6) -> 251.94 | F6: DOMO DECOR MOVIL | G6: 302M
A7: 35000LC3 | B7: MARCO PA PICAP/COND LACADO 3 ESP. 1 | C7: 345.6 | D7: 0.25 | E7: =C7*(1-D7) -> 259.2 | F7: DOMO DECOR MOVIL | G7: 302M
A8: 35000LC5 | B8: MARCO PA PICAP/COND LACADO 5 MADERA | C8: 387.6 | D8: 0.25 | E8: =C8*(1-D8) -> 290.7 | F8: DOMO DECOR MOVIL | G8: 302M
A9: 35000LC6 | B9: MARCO PA PICAP/COND LACADO 6 ESP. 2 | C9: 355.29 | D9: 0.25 | E9: =C9*(1-D9) -> 266.4675 | F9: DOMO DECOR MOVIL | G9: 302M
A10: 35000LC7 | B10: MARCO PA PICAP/COND LACADO 7 ESP. 3 | C10: 371.44 | D10: 0.25 | E10: =C10*(1-D10) -> 278.58 | F10: DOMO DECOR MOVIL | G10: 302M
A11: 35000MS | B11: MARCO PA PICAP/COND LAC.MARS (OXIDO) | C11: 326.29 | D11: 0.25 | E11: =C11*(1-D11) -> 244.7175 | F11: DOMO DECOR MOVIL | G11: 302M
A12: 35000NE | B12: MARCO PA PICAP/COND LAC.NEGRO MATE | C12: 322.99 | D12: 0.25 | E12: =C12*(1-D12) -> 242.2425 | F12: DOMO DECOR MOVIL | G12: 302M
A13: 35000NT | B13: MARCO PA PICAP/COND LAC.NEGRO TEXTURADO | C13: 322.99 | D13: 0.25 | E13: =C13*(1-D13) -> 242.2425 | F13: DOMO DECOR MOVIL | G13: 302M
A14: 35000NTXL | B14: MARCO PA PICAP/COND LAC. NEGRO TEXTURADO XL | C14: 645.99 | D14: 0.25 | E14: =C14*(1-D14) -> 484.4925 | F14: DOMO DECOR MOVIL | G14: 302M
... A660: 35908NT65 | B660: TAPA MARCO 46MM D-DECOR FIJO NEGRO TEXTURADO 6,5 MTS | C660: 30.35 | D660: 0.25 | E660: =C660*(1-D660) -> 22.7625 | F660: DOMO DECOR FIJO | G660: 302F
